{
  "device_info": [
    {
      "name": "loop0",
      "size": "55.5M",
      "type": "loop",
      "mountpoint": "/snap/core18/2344"
    },
    {
      "name": "loop1",
      "size": "55.5M",
      "type": "loop",
      "mountpoint": "/snap/core18/2284"
    },
    {
      "name": "loop2",
      "size": "528.2M",
      "type": "loop",
      "mountpoint": "/snap/pycharm-community/274"
    },
    {
      "name": "loop3",
      "size": "191M",
      "type": "loop",
      "mountpoint": "/snap/postman/176"
    },
    {
      "name": "loop4",
      "size": "43.6M",
      "type": "loop",
      "mountpoint": "/snap/snapd/14978"
    },
    {
      "name": "loop5",
      "size": "1.6M",
      "type": "loop",
      "mountpoint": "/snap/task/95"
    },
    {
      "name": "loop6",
      "size": "1.6M",
      "type": "loop",
      "mountpoint": "/snap/task/97"
    },
    {
      "name": "loop7",
      "size": "67.8M",
      "type": "loop",
      "mountpoint": "/snap/lxd/22753"
    },
    {
      "name": "loop8",
      "size": "67.9M",
      "type": "loop",
      "mountpoint": "/snap/lxd/22526"
    },
    {
      "name": "loop9",
      "size": "61.9M",
      "type": "loop",
      "mountpoint": "/snap/core20/1361"
    },
    {
      "name": "loop10",
      "size": "43.6M",
      "type": "loop",
      "mountpoint": "/snap/snapd/15177"
    },
    {
      "name": "loop11",
      "size": "61.9M",
      "type": "loop",
      "mountpoint": "/snap/core20/1405"
    },
    {
      "name": "\u251c\u2500nvme0n1p2",
      "size": "1G",
      "type": "part",
      "mountpoint": "/boot"
    },
    {
      "name": "\u2514\u2500ubuntu--vg-ubuntu--lv",
      "size": "49G",
      "type": "lvm",
      "mountpoint": "/"
    }
  ],
  "var/log/cloud-init.log": {
    "exists": true,
    "matches": [
      {
        "line": 17,
        "content": "2021-11-17 22:25:56,906 - cc_rightscale_userdata.py[DEBUG]: Failed to get raw userdata in module rightscale_userdata"
      },
      {
        "line": 69,
        "content": "2021-11-17 22:25:56,939 - cc_final_message.py[WARNING]: Used fallback datasource"
      },
      {
        "line": 77,
        "content": "2021-11-17 22:25:56,943 - main.py[DEBUG]: Ran 22 modules with 0 failures"
      }
    ],
    "error": null
  },
  "var/log/cloud-init-output.log": {
    "exists": true,
    "matches": [
      {
        "line": 100,
        "content": "2021-11-17 22:25:56,939 - cc_final_message.py[WARNING]: Used fallback datasource"
      }
    ],
    "error": null
  },
  "var/log/amazon/ssm/amazon-ssm-agent.log": {
    "exists": true,
    "matches": [
      {
        "line": 23,
        "content": "\"standardOutput\": \"2021-11-17 22:25:56,904 - handlers.py[DEBUG]: finish: modules-final/config-salt-minion: SUCCESS: config-salt-minion ran successfully\\n2021-11-17 22:25:56,904 - stages.py[DEBUG]: Running module reset_rmc (\\u003cmodule 'cloudinit.config.cc_reset_rmc' from '/usr/lib/python3/dist-packages/cloudinit/config/cc_reset_rmc.py'\\u003e) with frequency once-per-instance\\n2021-11-17 22:25:56,904 - handlers.py[DEBUG]: start: modules-final/config-reset_rmc: running config-reset_rmc with frequency once-per-instance\\n2021-11-17 22:25:56,904 - util.py[DEBUG]: Writing to /var/lib/cloud/instances/iid-datasource-none/sem/config_reset_rmc - wb: [644] 24 bytes\\n2021-11-17 22:25:56,904 - helpers.py[DEBUG]: Running config-reset_rmc using lock (\\u003cFileLock using file '/var/lib/cloud/instances/iid-datasource-none/sem/config_reset_rmc'\\u003e)\\n2021-11-17 22:25:56,905 - cc_reset_rmc.py[DEBUG]: Skipping creation of new ct_node_id node\\n2021-11-17 22:25:56,905 - handlers.py[DEBUG]: finish: modules-final/config-reset_rmc: SUCCESS: config-reset_rmc ran successfully\\n2021-11-17 22:25:56,905 - stages.py[DEBUG]: Running module refresh_rmc_and_interface (\\u003cmodule 'cloudinit.config.cc_refresh_rmc_and_interface' from '/usr/lib/python3/dist-packages/cloudinit/config/cc_refresh_rmc_and_interface.py'\\u003e) with frequency always\\n2021-11-17 22:25:56,905 - handlers.py[DEBUG]: start: modules-final/config-refresh_rmc_and_interface: running config-refresh_rmc_and_interface with frequency always\\n2021-11-17 22:25:56,905 - helpers.py[DEBUG]: Running config-refresh_rmc_and_interface using lock (\\u003ccloudinit.helpers.DummyLock object at 0x7f1aaf4e1250\\u003e)\\n2021-11-17 22:25:56,905 - cc_refresh_rmc_and_interface.py[DEBUG]: No 'rmcctrl' in path, disabled\\n2021-11-17 22:25:56,905 - handlers.py[DEBUG]: finish: modules-final/config-refresh_rmc_and_interface: SUCCESS: config-refresh_rmc_and_interface ran successfully\\n2021-11-17 22:25:56,905 - stages.py[DEBUG]: Running module rightscale_userdata (\\u003cmodule 'cloudinit.config.cc_rightscale_userdata' from '/usr/lib/python3/dist-packages/cloudinit/config/cc_rightscale_userdata.py'\\u003e) with frequency once-per-instance\\n2021-11-17 22:25:56,905 - handlers.py[DEBUG]: start: modules-final/config-rightscale_userdata: running config-rightscale_userdata with frequency once-per-instance\\n2021-11-17 22:25:56,905 - util.py[DEBUG]: Writing to /var/lib/cloud/instances/iid-datasource-none/sem/config_rightscale_userdata - wb: [644] 24 bytes\\n2021-11-17 22:25:56,906 - helpers.py[DEBUG]: Running config-rightscale_userdata using lock (\\u003cFileLock using file '/var/lib/cloud/instances/iid-datasource-none/sem/config_rightscale_userdata'\\u003e)\\n2021-11-17 22:25:56,906 - cc_rightscale_userdata.py[DEBUG]: Failed to get raw userdata in module rightscale_userdata\\n2021-11-17 22:25:56,906 - handlers.py[DEBUG]: finish: modules-final/config-rightscale_userdata: SUCCESS: config-rightscale_userdata ran successfully\\n2021-11-17 22:25:56,906 - stages.py[DEBUG]: Running module scripts-vendor (\\u003cmodule 'cloudinit.config.cc_scripts_vendor' from '/usr/lib/python3/dist-packages/cloudinit/config/cc_scripts_vendor.py'\\u003e) with frequency once-per-instance\\n2021-11-17 22:25:56,906 - handlers.py[DEBUG]: start: modules-final/config-scripts-vendor: running config-scripts-vendor with frequency once-per-instance\\n2021-11-17 22:25:56,906 - util.py[DEBUG]: Writing to /var/lib/cloud/instances/iid-datasource-none/sem/config_scripts_vendor - wb: [644] 25 bytes\\n2021-11-17 22:25:56,906 - helpers.py[DEBUG]: Running config-scripts-vendor using lock (\\u003cFileLock using file '/var/lib/cloud/instances/iid-datasource-none/sem/config_scripts_vendor'\\u003e)\\n2021-11-17 22:25:56,906 - handlers.py[DEBUG]: finish: modules-final/config-scripts-vendor: SUCCESS: config-scripts-vendor ran successfully\\n2021-11-17 22:25:56,906 - stages.py[DEBUG]: Running module scripts-per-once (\\u003cmodule 'cloudinit.config.cc_scripts_per_once' from '/usr/lib/python3/dist-packages/cloudinit/config/cc_scripts_per_once.py'\\u003e) with frequency once\\n2021-11-17 22:25:56,906 - handlers.py[DEBUG]: start: modules-final/config-scripts-per-once: running config-scripts-per-once with frequency once\\n2021-11-17 22:25:56,907 - util.py[DEBUG]: Writing to /var/lib/cloud/sem/config_scripts_per_once.once - wb: [644] 25 bytes\\n2021-11-17 22:25:56,907 - helpers.py[DEBUG]: Running config-scripts-per-once using lock (\\u003cFileLock using file '/var/lib/cloud/sem/config_scripts_per_once.once'\\u003e)\\n2021-11-17 22:25:56,907 - handlers.py[DEBUG]: finish: modules-final/config-scripts-per-once: SUCCESS: config-scripts-per-once ran successfully\\n2021-11-17 22:25:56,907 - stages.py[DEBUG]: Running module scripts-per-boot (\\u003cmodule 'cloudinit.config.cc_scripts_per_boot' from '/usr/lib/python3/dist-packages/cloudinit/config/cc_scripts_per_boot.py'\\u003e) with frequency always\\n2021-11-17 22:25:56,907 - handlers.py[DEBUG]: start: modules-final/config-scripts-per-boot: running config-scripts-per-boot with frequency always\\n2021-11-17 22:25:56,907 - helpers.py[DEBUG]: Running config-scripts-per-boot using lock (\\u003ccloudinit.helpers.DummyLock object at 0x7f1aaf441790\\u003e)\\n2021-11-17 22:25:56,907 - handlers.py[DEBUG]: finish: modules-final/config-scripts-per-boot: SUCCESS: config-scripts-per-boot ran successfully\\n2021-11-17 22:25:56,907 - stages.py[DEBUG]: Running module scripts-per-instance (\\u003cmodule 'cloudinit.config.cc_scripts_per_instance' from '/usr/lib/python3/dist-packages/cloudinit/config/cc_scripts_per_instance.py'\\u003e) with frequency once-per-instance\\n2021-11-17 22:25:56,907 - handlers.py[DEBUG]: start: modules-final/config-scripts-per-instance: running config-scripts-per-instance with frequency once-per-instance\\n2021-11-17 22:25:56,907 - util.py[DEBUG]: Writing to /var/lib/cloud/instances/iid-datasource-none/sem/config_scripts_per_instance - wb: [644] 25 bytes\\n2021-11-17 22:25:56,908 - helpers.py[DEBUG]: Running config-scripts-per-instance using lock (\\u003cFileLock using file '/var/lib/cloud/instances/iid-datasource-none/sem/config_scripts_per_instance'\\u003e)\\n2021-11-17 22:25:56,908 - handlers.py[DEBUG]: finish: modules-final/config-scripts-per-instance: SUCCESS: config-scripts-per-instance ran successfully\\n2021-11-17 22:25:56,908 - stages.py[DEBUG]: Running module scripts-user (\\u003cmodule 'cloudinit.config.cc_scripts_user' from '/usr/lib/python3/dist-packages/cloudinit/config/cc_scripts_user.py'\\u003e) with frequency once-per-instance\\n2021-11-17 22:25:56,908 - handlers.py[DEBUG]: start: modules-final/config-scripts-user: running config-scripts-user with frequency once-per-instance\\n2021-11-17 22:25:56,908 - util.py[DEBUG]: Writing to /var/lib/cloud/instances/iid-datasource-none/sem/config_scripts_user - wb: [644] 25 bytes\\n2021-11-17 22:25:56,908 - helpers.py[DEBUG]: Running config-scripts-user using lock (\\u003cFileLock using file '/var/lib/cloud/instances/iid-datasource-none/sem/config_scripts_user'\\u003e)\\n2021-11-17 22:25:56,908 - handlers.py[DEBUG]: finish: modules-final/config-scripts-user: SUCCESS: config-scripts-user ran successfully\\n2021-11-17 22:25:56,908 - stages.py[DEBUG]: Running module ssh-authkey-fingerprints (\\u003cmodule 'cloudinit.config.cc_ssh_authkey_fingerprints' from '/usr/lib/python3/dist-packages/cloudinit/config/cc_ssh_authkey_fingerprints.py'\\u003e) with frequency once-per-instance\\n2021-11-17 22:25:56,909 - handlers.py[DEBUG]: start: modules-final/config-ssh-authkey-fingerprints: running config-ssh-authkey-fingerprints with frequency once-per-instance\\n2021-11-17 22:25:56,909 - util.py[DEBUG]: Writing to /var/lib/cloud/instances/iid-datasource-none/sem/config_ssh_authkey_fingerprints - wb: [644] 24 bytes\\n2021-11-17 22:25:56,909 - helpers.py[DEBUG]: Running config-ssh-authkey-fingerprints using lock (\\u003cFileLock using file '/var/lib/cloud/instances/iid-datasource-none/sem/config_ssh_authkey_fingerprints'\\u003e)\\n2021-11-17 22:25:56,909 - util.py[DEBUG]: Reading from /etc/ssh/sshd_config (quiet=False)\\n2021-11-17 22:25:56,909 - util.py[DEBUG]: Read 3316 bytes from /etc/ssh/sshd_config\\n2021-11-17 22:25:56,910 - handlers.py[DEBUG]: finish: modules-final/config-ssh-authkey-fingerprints: SUCCESS: config-ssh-authkey-fingerprints ran successfully\\n2021-11-17 22:25:56,910 - stages.py[DEBUG]: Running module keys-to-console (\\u003cmodule 'cloudinit.config.cc_keys_to_console' from '/usr/lib/python3/dist-packages/cloudinit/config/cc_keys_to_console.py'\\u003e) with frequency once-per-instance\\n2021-11-17 22:25:56,910 - handlers.py[DEBUG]: start: modules-final/config-keys-to-console: running config-keys-to-console with frequency once-per-instance\\n2021-11-17 22:25:56,910 - util.py[DEBUG]: Writing to /var/lib/cloud/instances/iid-datasource-none/sem/config_keys_to_console - wb: [644] 24 bytes\\n2021-11-17 22:25:56,910 - helpers.py[DEBUG]: Running config-keys-to-console using lock (\\u003cFileLock using file '/var/lib/cloud/instances/iid-datasource-none/sem/config_keys_to_console'\\u003e)\\n2021-11-17 22:25:56,910 - subp.py[DEBUG]: Running command ['/usr/lib/cloud-init/write-ssh-key-fingerprints', '', 'ssh-dss'] with allowed return codes [0] (shell=False, capture=True)\\n2021-11-17 22:25:56,935 - handlers.py[DEBUG]: finish: modules-final/config-keys-to-console: SUCCESS: config-keys-to-console ran successfully\\n2021-11-17 22:25:56,935 - stages.py[DEBUG]: Running module phone-home (\\u003cmodule 'cloudinit.config.cc_phone_home' from '/usr/lib/python3/dist-packages/cloudinit/config/cc_phone_home.py'\\u003e) with frequency once-per-instance\\n2021-11-17 22:25:56,935 - handlers.py[DEBUG]: start: modules-final/config-phone-home: running config-phone-home with frequency once-per-instance\\n2021-11-17 22:25:56,935 - util.py[DEBUG]: Writing to /var/lib/cloud/instances/iid-datasource-none/sem/config_phone_home - wb: [644] 25 bytes\\n2021-11-17 22:25:56,935 - helpers.py[DEBUG]: Running config-phone-home using lock (\\u003cFileLock using file '/var/lib/cloud/instances/iid-datasource-none/sem/config_phone_home'\\u003e)\\n2021-11-17 22:25:56,936 - cc_phone_home.py[DEBUG]: Skipping module named phone-home, no 'phone_home' configuration found\\n2021-11-17 22:25:56,936 - handlers.py[DEBUG]: finish: modules-final/config-phone-home: SUCCESS: config-phone-home ran successfully\\n2021-11-17 22:25:56,936 - stages.py[DEBUG]: Running module final-message (\\u003cmodule 'cloudinit.config.cc_final_message' from '/usr/lib/python3/dist-packages/cloudinit/config/cc_final_message.py'\\u003e) with frequency always\\n2021-11-17 22:25:56,936 - handlers.py[DEBUG]: start: modules-final/config-final-message: running config-final-message with frequency always\\n2021-11-17 22:25:56,936 - helpers.py[DEBUG]: Running config-final-message using lock (\\u003ccloudinit.helpers.DummyLock object at 0x7f1aaf482cd0\\u003e)\\n2021-11-17 22:25:56,936 - util.py[DEBUG]: Reading from /proc/uptime (quiet=False)\\n2021-11-17 22:25:56,936 - util.py[DEBUG]: Read 11 bytes from /proc/uptime\\n2021-11-17 22:25:56,939 - util.py[DEBUG]: Cloud-init v. 21.2-3-g899bfaa9-0ubuntu2~20.04.1 finished at Wed, 17 Nov 2021 22:25:56 +0000. Datasource DataSourceNone.  Up 21.52 seconds\\n2021-11-17 22:25:56,939 - util.py[DEBUG]: Writing to /var/lib/cloud/instance/boot-finished - wb: [644] 79 bytes\\n2021-11-17 22:25:56,939 - cc_final_message.py[WARNING]: Used fallback datasource\\n2021-11-17 22:25:56,942 - handlers.py[DEBUG]: finish: modules-final/config-final-message: SUCCESS: config-final-message ran successfully\\n2021-11-17 22:25:56,942 - stages.py[DEBUG]: Running module power-state-change (\\u003cmodule 'cloudinit.config.cc_power_state_change' from '/usr/lib/python3/dist-packages/cloudinit/config/cc_power_state_change.py'\\u003e) with frequency once-per-instance\\n2021-11-17 22:25:56,942 - handlers.py[DEBUG]: start: modules-final/config-power-state-change: running config-power-state-change with frequency once-per-instance\\n2021-11-17 22:25:56,943 - util.py[DEBUG]: Writing to /var/lib/cloud/instances/iid-datasource-none/sem/config_power_state_change - wb: [644] 25 bytes\\n2021-11-17 22:25:56,943 - helpers.py[DEBUG]: Running config-power-state-change using lock (\\u003cFileLock using file '/var/lib/cloud/instances/iid-datasource-none/sem/config_power_state_change'\\u003e)\\n2021-11-17 22:25:56,943 - cc_power_state_change.py[DEBUG]: no power_state provided. doing nothing\\n2021-11-17 22:25:56,943 - handlers.py[DEBUG]: finish: modules-final/config-power-state-change: SUCCESS: config-power-state-change ran successfully\\n2021-11-17 22:25:56,943 - main.py[DEBUG]: Ran 22 modules with 0 failures\\n2021-11-17 22:25:56,943 - atomic_helper.py[DEBUG]: Atomically writing to file /var/lib/cloud/data/status.json (via temporary file /var/lib/cloud/data/tmpew6khi0e) - w: [644] 567 bytes/chars\\n2021-11-17 22:25:56,943 - atomic_helper.py[DEBUG]: Atomically writing to file /var/lib/cloud/data/result.json (via temporary file /var/lib/cloud/data/tmpt_2qfeth) - w: [644] 65 bytes/chars\\n2021-11-17 22:25:56,944 - util.py[DEBUG]: Creating symbolic link from '/run/cloud-init/result.json' =\\u003e '../../var/lib/cloud/data/result.json'\\n2021-11-17 22:25:56,944 - util.py[DEBUG]: Reading from /proc/uptime (quiet=False)\\n2021-11-17 22:25:56,944 - util.py[DEBUG]: Read 11 bytes from /proc/uptime\\n2021-11-17 22:25:56,944 - util.py[DEBUG]: cloud-init mode 'modules' took 0.126 seconds (0.13)\\n2021-11-17 22:25:56,944 - handlers.py[DEBUG]: finish: modules-final: SUCCESS: running modules for final\\n2021-11-18 13:45:02,822 - hotplug_hook.py[DEBUG]: hotplug-hook called with the following arguments: {hotplug_action: query, subsystem: net, udevaction: None, devpath: None}\\n2021-11-18 13:45:02,824 - handlers.py[DEBUG]: start: hotplug-hook: Handle reconfiguration on hotplug events\\n2021-11-18 13:45:02,824 - hotplug_hook.py[DEBUG]: Fetching datasource\\n2021-11-18 13:45:02,824 - handlers.py[DEBUG]: start: hotplug-hook/check-cache: attempting to read from cache [trust]\\n2021-11-18 13:45:02,824 - util.py[DEBUG]: Reading from /var/lib/cloud/instance/obj.pkl (quiet=False)\\n2021-11-18 13:45:02,825 - util.py[DEBUG]: Read 8375 bytes from /var/lib/cloud/instance/obj.pkl\\n2021-11-18 13:45:02,831 - util.py[DEBUG]: Reading from /run/cloud-init/.instance-id (quiet=False)\\n2021-11-18 13:45:02,832 - util.py[DEBUG]: Read 20 bytes from /run/cloud-init/.instance-id\\n2021-11-18 13:45:02,832 - stages.py[DEBUG]: restored from cache with run check: DataSourceNone\\n2021-11-18 13:45:02,832 - handlers.py[DEBUG]: finish: hotplug-hook/check-cache: SUCCESS: restored from cache with run check: DataSourceNone\\n2021-11-18 13:45:02,832 - hotplug_hook.py[DEBUG]: hotplug not supported for event of type net\\n2021-11-18 13:45:02,832 - handlers.py[DEBUG]: finish: hotplug-hook: SUCCESS: Handle reconfiguration on hotplug events\\n2021-11-18 13:45:02,832 - hotplug_hook.py[DEBUG]: Exiting hotplug handler\\n2021-11-18 13:45:02,832 - util.py[DEBUG]: Reading from /proc/uptime (quiet=False)\\n2021-11-18 13:45:02,832 - util.py[DEBUG]: Read 18 bytes from /proc/uptime\\n2021-11-18 13:45:02,832 - util.py[DEBUG]: cloud-init mode 'hotplug-hook' took 0.063 seconds (0.06)\\n\","
      },
      {
        "line": 24,
        "content": "\"standardError\": \"\""
      },
      {
        "line": 35,
        "content": "2025-04-18 23:59:00.3919 INFO [ssm-agent-worker] [MessageService] [MGSInteractor] Parsing AgentMessage b3e05523-f102-44f9-9736-ad3aad1ba004, Payload: {\"schemaVersion\":1,\"jobId\":\"aws.ssm.e61e28af-4cba-49a1-8a9a-229166f573aa.i-0008416fc47ed613e\",\"topic\":\"aws.ssm.sendCommand\",\"content\":\"{\\\"OutputS3KeyPrefix\\\":\\\"\\\",\\\"CloudWatchOutputEnabled\\\":\\\"false\\\",\\\"Parameters\\\":{\\\"commands\\\":[\\\"tail -100 /var/log/cloud-init-output.log\\\"]},\\\"DocumentContent\\\":{\\\"schemaVersion\\\":\\\"1.2\\\",\\\"description\\\":\\\"Run a shell script or specify the commands to run.\\\",\\\"runtimeConfig\\\":{\\\"aws:runShellScript\\\":{\\\"properties\\\":[{\\\"workingDirectory\\\":\\\"{{ workingDirectory }}\\\",\\\"timeoutSeconds\\\":\\\"{{ executionTimeout }}\\\",\\\"runCommand\\\":\\\"{{ commands }}\\\",\\\"id\\\":\\\"0.aws:runShellScript\\\"}]}},\\\"parameters\\\":{\\\"executionTimeout\\\":{\\\"default\\\":\\\"3600\\\",\\\"description\\\":\\\"(Optional) The time in seconds for a command to complete before it is considered to have failed. Default is 3600 (1 hour). Maximum is 172800 (48 hours).\\\",\\\"type\\\":\\\"String\\\",\\\"allowedPattern\\\":\\\"([1-9][0-9]{0,4})|(1[0-6][0-9]{4})|(17[0-1][0-9]{3})|(172[0-7][0-9]{2})|(172800)\\\"},\\\"workingDirectory\\\":{\\\"default\\\":\\\"\\\",\\\"description\\\":\\\"(Optional) The path to the working directory on your instance.\\\",\\\"maxChars\\\":4096,\\\"type\\\":\\\"String\\\"},\\\"commands\\\":{\\\"minItems\\\":1,\\\"displayType\\\":\\\"textarea\\\",\\\"description\\\":\\\"(Required) Specify a shell script or a command to run.\\\",\\\"type\\\":\\\"StringList\\\"}}},\\\"CloudWatchLogGroupName\\\":\\\"\\\",\\\"OutputS3Region\\\":\\\"us-east-2\\\",\\\"CommandId\\\":\\\"e61e28af-4cba-49a1-8a9a-229166f573aa\\\",\\\"OutputS3BucketName\\\":\\\"\\\",\\\"DocumentName\\\":\\\"AWS-RunShellScript\\\"}\"}"
      },
      {
        "line": 60,
        "content": "2025-04-18 23:59:00.4050 WARN [ssm-agent-worker] [MessageService] [MGSInteractor] acknowledgement e031a827-4496-463e-97e4-b0cd1893aa60 received but could not find any reply threads running"
      }
    ],
    "error": null
  },
  "var/log/syslog": {
    "exists": true,
    "matches": [
      {
        "line": 3,
        "content": "Apr 18 23:05:36 expert-cws gnome-shell[1408]: cr_parser_new_from_buf: assertion 'a_buf && a_len' failed"
      },
      {
        "line": 4,
        "content": "Apr 18 23:05:36 expert-cws gnome-shell[1408]: cr_declaration_parse_list_from_buf: assertion 'parser' failed"
      },
      {
        "line": 5,
        "content": "Apr 18 23:05:36 expert-cws gsd-media-keys[1527]: Failed to grab accelerator for keybinding settings:hibernate"
      },
      {
        "line": 6,
        "content": "Apr 18 23:05:36 expert-cws gsd-media-keys[1527]: Failed to grab accelerator for keybinding settings:rfkill"
      },
      {
        "line": 7,
        "content": "Apr 18 23:05:36 expert-cws gsd-media-keys[1527]: Failed to grab accelerator for keybinding settings:playback-random"
      },
      {
        "line": 8,
        "content": "Apr 18 23:05:36 expert-cws gsd-media-keys[1527]: Failed to grab accelerator for keybinding settings:playback-repeat"
      },
      {
        "line": 9,
        "content": "Apr 18 23:05:36 expert-cws gsd-color[1519]: failed to get edid: unable to get EDID for output"
      },
      {
        "line": 12,
        "content": "Apr 18 23:05:39 expert-cws gnome-shell[1408]: cr_parser_new_from_buf: assertion 'a_buf && a_len' failed"
      },
      {
        "line": 13,
        "content": "Apr 18 23:05:39 expert-cws gnome-shell[1408]: cr_declaration_parse_list_from_buf: assertion 'parser' failed"
      },
      {
        "line": 14,
        "content": "Apr 18 23:05:57 expert-cws pulseaudio[1475]: GetManagedObjects() failed: org.freedesktop.DBus.Error.NoReply: Did not receive a reply. Possible causes include: the remote application did not send a reply, the message bus security policy blocked the reply, the reply timeout expired, or the network connection was broken."
      },
      {
        "line": 33,
        "content": "Apr 18 23:10:42 expert-cws gnome-shell[1408]: cr_parser_new_from_buf: assertion 'a_buf && a_len' failed"
      },
      {
        "line": 34,
        "content": "Apr 18 23:10:42 expert-cws gnome-shell[1408]: cr_declaration_parse_list_from_buf: assertion 'parser' failed"
      },
      {
        "line": 41,
        "content": "Apr 18 23:14:28 expert-cws snapd[654]: stateengine.go:149: state ensure error: Post https://api.snapcraft.io/v2/snaps/refresh: proxyconnect tcp: dial tcp: lookup sj-proxy.ccie.cisco.com: no such host"
      },
      {
        "line": 67,
        "content": "Apr 18 23:26:40 expert-cws multipath: nvme1n1: failed to get udev uid: Invalid argument"
      },
      {
        "line": 96,
        "content": "Apr 18 23:49:18 expert-cws apt-helper[2254]: E: Sub-process nm-online returned an error code (1)"
      },
      {
        "line": 97,
        "content": "Apr 18 23:49:52 expert-cws apt.systemd.daily[2321]: The URI http://sj-prov-devnet.ccie.cisco.com/ubuntu/mirror/archive.ubuntu.com/ubuntu/pool/main/v/vim/xxd_8.1.2269-1ubuntu5.7_amd64.deb failed to download, aborting"
      }
    ],
    "error": null
  },
  "var/log/messages": {
    "exists": false,
    "matches": [],
    "error": "tail: cannot open '/var/log/messages' for reading: No such file or directory\nfailed to run commands: exit status 1"
  }
}